Workbook

Sheet Hoja 1 - Supabase Transcripts
A1: Session Deep Dives | X1: General Data | AA1: Survey Data | AG1: Text Segregation by Topic | AM1: Text Processing & Engagement | AW1: Sentiment Topics | BU1: Sentiment Analysis | CB1: Negative Issue Detection | CF1: Reflection & Thinking Depth | CJ1: Emotion Analysis | CQ1: AI Disclosure gap | CZ1: Reviwerer 1 Disclosure Gap | DP1: Audit Week | DQ1: Cohens k | EC1: Second Reviewer | ES1: Extra
A2: session_id | B2: audit_id | C2: employee_id | D2: channel | E2: started_at | F2: ended_at | G2: status | H2: duration_sec | I2: media_uri | J2: eleven_conversation_id | K2: eleven_agent_id | L2: transcription | M2: aud_id | N2: summary | O2: caller_phone | P2: called_phone | Q2: source_provider | R2: survey_result_ids | S2: interview_tag | T2: interview_tag_source | U2: interview_tag_updated_at | V2: interview_tag_updated_by | W2: ai_analysis_complete | X2: week_number | Y2: participant_text_clean | Z2: session_number_per_employee | AA2: pre-survey_response_json | AB2: pre-survey_submitted_at | AC2: post-survey_response_json | AD2: post-survey_submitted_at | AE2: post_feedback_topic | AF2: post_feedback_sentiment | AG2: text_overall_experience | AH2: text_workload_sustainability | AI2: text_client_value | AJ2: text_leadership_engagement | AK2: text_additional_topic | AL2: text_closing | AM2: word_count_total | AN2: word_count_overall | AO2: word_count_workload_sustainability | AP2: word_count_client_value | AQ2: word_count_leadership_engagement | AR2: word_count_additional_topic | AS2: word_count_closing | AT2: participant_turn_count | AU2: avg_words_per_turn | AV2: longest_response_words | AW2: sentiment_overall experience | AX2: soe_pos | AY2: soe_neu | AZ2: soe_neg | BA2: sentiment_workload | BB2: sw_pos | BC2: sw_neu | BD2: sw_neg | BE2: sentiment_client_value | BF2: scv_pos | BG2: scv_neu | BH2: scv_neg | BI2: sentiment_leadership | BJ2: sl_pos | BK2: sl_neu | BL2: sl_neg | BM2: sentiment_additional_ topic | BN2: sat_pos | BO2: sat_neu | BP2: sat_neg | BQ2: sentiment_closing | BR2: sc_pos | BS2: sc_neu | BT2: sc_neg | BU2: sentiment_positive_avg | BV2: sentiment_neutral_avg | BW2: sentiment_negative_avg | BX2: sentiment_negative_max | BY2: sentiment_label_dominant | BZ2: sentiment_complete_interview | CA2: sentiment_manual_negative | CB2: negative_issue_auto | CC2: negative_issue_keyword_count | CD2: deep_dive_negative_issue | CE2: negative_issue_manual | CF2: causal_marker_count (e.g., because, due to, led to) | CG2: consequence_marker_count (e.g., resulted in, impact) (e.g., resulted in, impact) | CH2: improvement_marker_count (e.g., should, need to, could) | CI2: reflection_depth_manual | CJ2: emotion_general | CK2: emotion_overall_experience | CL2: emotion_workload_sustainability | CM2: emotion_client_value | CN2: emotion_leadership_engagement | CO2: emotion_additional_topic | CP2: emotion_closing | CQ2: Disclosure gap | CR2: gap_overall_expierience | CS2: reason_o_e | CT2: gap_workload_sust | CU2: reason_w_s | CV2: gap_client_value | CW2: reason_c_v | CX2: gap_leadership_eng | CY2: reason_l_e | CZ2: manual_gap_overall_experience | DA2: manual_likert_overall_experience | DB2: gap_segmentation_overall experience | DC2: negative_issue_overall_experience | DD2: manual_gap_workload_sust | DE2: manual_likert_workload_sust | DF2: gap_segmentation_workload_sust | DG2: negative_issue_workload_sust | DH2: manual_gap_client_value | DI2: manual_likert_client_value | DJ2: gap_segmentation_client_value | DK2: negative_issue_client_value | DL2: manual_gap_leadership | DM2: manual_likert_leadership | DN2: gap_segmentation_leadership | DO2: negative_issue_leadership | DP2: audit_week | DQ2: da_1 | DR2: dm_1 | DS2: da_2 | DT2: dm_2 | DU2: da_3 | DV2: dm_3 | DW2: da_4 | DX2: dm_4 | DY2: diif_1 | DZ2: diif_2 | EA2: diif_3 | EB2: diif_4 | EC2: manual_gap_overall_experience_2 | ED2: manual_likert_overall_experience_2 | EE2: gap_segmentation_overall experience_2 | EF2: negative_issue_overall_experience_2 | EG2: manual_gap_workload_sust_2 | EH2: manual_likert_workload_sust_2 | EI2: gap_segmentation_workload_sust_2 | EJ2: negative_issue_workload_sust_2 | EK2: manual_gap_client_value_2 | EL2: manual_likert_client_value_2 | EM2: gap_segmentation_client_value_2 | EN2: negative_issue_client_value_2 | EO2: manual_gap_leadership_2 | EP2: manual_likert_leadership_2 | EQ2: gap_segmentation_leadership_2 | ER2: negative_issue_leadership_2 | ES2: Willingess-to-repeat | ET2: Gap Manual | EU2: Gap Prevalence by Threshold workload sustainability | EV2: Gap Prevalence by Threshold client value | EW2: Gap Prevalence by Threshold leadership engagement | EX2: Top Box - Gap Prevalence by Threshold workload sustainability | EY2: Top Box - Gap Prevalence by Threshold client value | EZ2: Top Box - Gap Prevalence by Threshold leadership engagement | FA2: Top Box - Gap | GP2: Disclaimer: All field in grey must be filled wth ElevenLabs-Data before running the scripts.
DQ3: =CR3 -> 0 | DR3: =DB3 -> 0 | DS3: =CT3 -> 0 | DT3: =DF3 -> 0 | DU3: =CV3 -> 0 | DV3: =DJ3 -> 0 | DW3: =CX3 -> 0 | DX3: =DN3 -> 0 | DY3: {=_xlfn.LET( _xlpm.a,LOWER(TRIM(DQ3&"")), _xlpm.b,LOWER(TRIM(DR3&"")), _xlpm.x,_xlfn.IFS(_xlpm.a="0",0,_xlpm.a="none",0,_xlpm.a="moderate",1,_xlpm.a="strong",2), _xlpm.y,_xlfn.IFS(_xlpm.b="0",0,_xlpm.b="none",0,_xlpm.b="moderate",1,_xlpm.b="strong",2), _xlpm.d,ABS(_xlpm.x-_xlpm.y), IF(_xlpm.d=0,"green",IF(_xlpm.d=1,"orange",IF(_xlpm.d=2,"red","check"))) )} -> green | DZ3: {=_xlfn.LET( _xlpm.a,LOWER(TRIM(DS3&"")), _xlpm.b,LOWER(TRIM(DT3&"")), _xlpm.x,_xlfn.IFS(_xlpm.a="0",0,_xlpm.a="none",0,_xlpm.a="moderate",1,_xlpm.a="strong",2), _xlpm.y,_xlfn.IFS(_xlpm.b="0",0,_xlpm.b="none",0,_xlpm.b="moderate",1,_xlpm.b="strong",2), _xlpm.d,ABS(_xlpm.x-_xlpm.y), IF(_xlpm.d=0,"green",IF(_xlpm.d=1,"orange",IF(_xlpm.d=2,"red","check"))) )} -> green | EA3: {=_xlfn.LET( _xlpm.a,LOWER(TRIM(DU3&"")), _xlpm.b,LOWER(TRIM(DV3&"")), _xlpm.x,_xlfn.IFS(_xlpm.a="0",0,_xlpm.a="none",0,_xlpm.a="moderate",1,_xlpm.a="strong",2), _xlpm.y,_xlfn.IFS(_xlpm.b="0",0,_xlpm.b="none",0,_xlpm.b="moderate",1,_xlpm.b="strong",2), _xlpm.d,ABS(_xlpm.x-_xlpm.y), IF(_xlpm.d=0,"green",IF(_xlpm.d=1,"orange",IF(_xlpm.d=2,"red","check"))) )} -> green | EB3: {=_xlfn.LET( _xlpm.a,LOWER(TRIM(DW3&"")), _xlpm.b,LOWER(TRIM(DX3&"")), _xlpm.x,_xlfn.IFS(_xlpm.a="0",0,_xlpm.a="none",0,_xlpm.a="moderate",1,_xlpm.a="strong",2), _xlpm.y,_xlfn.IFS(_xlpm.b="0",0,_xlpm.b="none",0,_xlpm.b="moderate",1,_xlpm.b="strong",2), _xlpm.d,ABS(_xlpm.x-_xlpm.y), IF(_xlpm.d=0,"green",IF(_xlpm.d=1,"orange",IF(_xlpm.d=2,"red","check"))) )} -> green | ES3: =IFERROR(VALUE(_xlfn.TEXTBEFORE(_xlfn.TEXTAFTER(AC3,"""84a544d4-0c20-4f9f-bb4b-dd698a9b0c0b"":"),",")),IFERROR(VALUE(_xlfn.TEXTBEFORE(_xlfn.TEXTAFTER(AC3,"""84a544d4-0c20-4f9f-bb4b-dd698a9b0c0b"":"),"}")),IFERROR(VALUE(_xlfn.TEXTBEFORE(_xlfn.TEXTAFTER(AC3,"""784c5905-6667-4dcd-906c-8b405a6572b6"":"),",")),IFERROR(VALUE(_xlfn.TEXTBEFORE(_xlfn.TEXTAFTER(AC3,"""784c5905-6667-4dcd-906c-8b405a6572b6"":"),"}")),"")))) | ET3: =IF(OR(DF3="Strong",DF3="Moderate",DJ3="Strong",DJ3="Moderate",DN3="Strong",DN3="Moderate"),"Yes","No") -> No | EU3: =IF(AND(DE3>=3,DD3=1),"Positive concordance",IF(AND(DE3>=3,DD3>=2),"Gap",IF(AND(DE3<=2,DD3>=2),"Negative concordance","Uninformative"))) -> Uninformative | EV3: =IF(AND(DI3>=3,DH3=1),"Positive concordance",IF(AND(DI3>=3,DH3>=2),"Gap",IF(AND(DI3<=2,DH3>=2),"Negative concordance","Uninformative"))) -> Uninformative | EW3: =IF(AND(DM3>=3,DL3=1),"Positive concordance",IF(AND(DM3>=3,DL3>=2),"Gap",IF(AND(DM3<=2,DL3>=2),"Negative concordance","Uninformative"))) -> Uninformative | EX3: =IF(AND(DE3=4,DD3=1),"Positive concordance",IF(AND(DE3=4,DD3>=2),"Gap",IF(AND(DE3<=3,DD3>=2),"Negative concordance","Uninformative"))) -> Uninformative | EY3: =IF(AND(DI3=4,DH3=1),"Positive concordance",IF(AND(DI3=4,DH3>=2),"Gap",IF(AND(DI3<=3,DH3>=2),"Negative concordance","Uninformative"))) -> Uninformative | EZ3: =IF(AND(DM3=4,DL3=1),"Positive concordance",IF(AND(DM3=4,DL3>=2),"Gap",IF(AND(DM3<=3,DL3>=2),"Negative concordance","Uninformative"))) -> Uninformative | FA3: =IF(OR(EX3="Gap",EY3="Gap",EZ3="Gap"),"Yes","No") -> No
DQ4: =CR4 -> 0 | DR4: =DB4 -> 0 | DS4: =CT4 -> 0 | DT4: =DF4 -> 0 | DU4: =CV4 -> 0 | DV4: =DJ4 -> 0 | DW4: =CX4 -> 0 | DX4: =DN4 -> 0 | DY4: {=_xlfn.LET( _xlpm.a,LOWER(TRIM(DQ4&"")), _xlpm.b,LOWER(TRIM(DR4&"")), _xlpm.x,_xlfn.IFS(_xlpm.a="0",0,_xlpm.a="none",0,_xlpm.a="moderate",1,_xlpm.a="strong",2), _xlpm.y,_xlfn.IFS(_xlpm.b="0",0,_xlpm.b="none",0,_xlpm.b="moderate",1,_xlpm.b="strong",2), _xlpm.d,ABS(_xlpm.x-_xlpm.y), IF(_xlpm.d=0,"green",IF(_xlpm.d=1,"orange",IF(_xlpm.d=2,"red","check"))) )} -> green | DZ4: {=_xlfn.LET( _xlpm.a,LOWER(TRIM(DS4&"")), _xlpm.b,LOWER(TRIM(DT4&"")), _xlpm.x,_xlfn.IFS(_xlpm.a="0",0,_xlpm.a="none",0,_xlpm.a="moderate",1,_xlpm.a="strong",2), _xlpm.y,_xlfn.IFS(_xlpm.b="0",0,_xlpm.b="none",0,_xlpm.b="moderate",1,_xlpm.b="strong",2), _xlpm.d,ABS(_xlpm.x-_xlpm.y), IF(_xlpm.d=0,"green",IF(_xlpm.d=1,"orange",IF(_xlpm.d=2,"red","check"))) )} -> green | EA4: {=_xlfn.LET( _xlpm.a,LOWER(TRIM(DU4&"")), _xlpm.b,LOWER(TRIM(DV4&"")), _xlpm.x,_xlfn.IFS(_xlpm.a="0",0,_xlpm.a="none",0,_xlpm.a="moderate",1,_xlpm.a="strong",2), _xlpm.y,_xlfn.IFS(_xlpm.b="0",0,_xlpm.b="none",0,_xlpm.b="moderate",1,_xlpm.b="strong",2), _xlpm.d,ABS(_xlpm.x-_xlpm.y), IF(_xlpm.d=0,"green",IF(_xlpm.d=1,"orange",IF(_xlpm.d=2,"red","check"))) )} -> green | EB4: {=_xlfn.LET( _xlpm.a,LOWER(TRIM(DW4&"")), _xlpm.b,LOWER(TRIM(DX4&"")), _xlpm.x,_xlfn.IFS(_xlpm.a="0",0,_xlpm.a="none",0,_xlpm.a="moderate",1,_xlpm.a="strong",2), _xlpm.y,_xlfn.IFS(_xlpm.b="0",0,_xlpm.b="none",0,_xlpm.b="moderate",1,_xlpm.b="strong",2), _xlpm.d,ABS(_xlpm.x-_xlpm.y), IF(_xlpm.d=0,"green",IF(_xlpm.d=1,"orange",IF(_xlpm.d=2,"red","check"))) )} -> green | ES4: =IFERROR(VALUE(_xlfn.TEXTBEFORE(_xlfn.TEXTAFTER(AC4,"""84a544d4-0c20-4f9f-bb4b-dd698a9b0c0b"":"),",")),IFERROR(VALUE(_xlfn.TEXTBEFORE(_xlfn.TEXTAFTER(AC4,"""84a544d4-0c20-4f9f-bb4b-dd698a9b0c0b"":"),"}")),IFERROR(VALUE(_xlfn.TEXTBEFORE(_xlfn.TEXTAFTER(AC4,"""784c5905-6667-4dcd-906c-8b405a6572b6"":"),",")),IFERROR(VALUE(_xlfn.TEXTBEFORE(_xlfn.TEXTAFTER(AC4,"""784c5905-6667-4dcd-906c-8b405a6572b6"":"),"}")),"")))) | ET4: =IF(OR(DF4="Strong",DF4="Moderate",DJ4="Strong",DJ4="Moderate",DN4="Strong",DN4="Moderate"),"Yes","No") -> No | EU4: =IF(AND(DE4>=3,DD4=1),"Positive concordance",IF(AND(DE4>=3,DD4>=2),"Gap",IF(AND(DE4<=2,DD4>=2),"Negative concordance","Uninformative"))) -> Uninformative | EV4: =IF(AND(DI4>=3,DH4=1),"Positive concordance",IF(AND(DI4>=3,DH4>=2),"Gap",IF(AND(DI4<=2,DH4>=2),"Negative concordance","Uninformative"))) -> Uninformative | EW4: =IF(AND(DM4>=3,DL4=1),"Positive concordance",IF(AND(DM4>=3,DL4>=2),"Gap",IF(AND(DM4<=2,DL4>=2),"Negative concordance","Uninformative"))) -> Uninformative | EX4: =IF(AND(DE4=4,DD4=1),"Positive concordance",IF(AND(DE4=4,DD4>=2),"Gap",IF(AND(DE4<=3,DD4>=2),"Negative concordance","Uninformative"))) -> Uninformative | EY4: =IF(AND(DI4=4,DH4=1),"Positive concordance",IF(AND(DI4=4,DH4>=2),"Gap",IF(AND(DI4<=3,DH4>=2),"Negative concordance","Uninformative"))) -> Uninformative | EZ4: =IF(AND(DM4=4,DL4=1),"Positive concordance",IF(AND(DM4=4,DL4>=2),"Gap",IF(AND(DM4<=3,DL4>=2),"Negative concordance","Uninformative"))) -> Uninformative | FA4: =IF(OR(EX4="Gap",EY4="Gap",EZ4="Gap"),"Yes","No") -> No
DQ5: =CR5 -> 0 | DR5: =DB5 -> 0 | DS5: =CT5 -> 0 | DT5: =DF5 -> 0 | DU5: =CV5 -> 0 | DV5: =DJ5 -> 0 | DW5: =CX5 -> 0 | DX5: =DN5 -> 0 | DY5: {=_xlfn.LET( _xlpm.a,LOWER(TRIM(DQ5&"")), _xlpm.b,LOWER(TRIM(DR5&"")), _xlpm.x,_xlfn.IFS(_xlpm.a="0",0,_xlpm.a="none",0,_xlpm.a="moderate",1,_xlpm.a="strong",2), _xlpm.y,_xlfn.IFS(_xlpm.b="0",0,_xlpm.b="none",0,_xlpm.b="moderate",1,_xlpm.b="strong",2), _xlpm.d,ABS(_xlpm.x-_xlpm.y), IF(_xlpm.d=0,"green",IF(_xlpm.d=1,"orange",IF(_xlpm.d=2,"red","check"))) )} -> green | DZ5: {=_xlfn.LET( _xlpm.a,LOWER(TRIM(DS5&"")), _xlpm.b,LOWER(TRIM(DT5&"")), _xlpm.x,_xlfn.IFS(_xlpm.a="0",0,_xlpm.a="none",0,_xlpm.a="moderate",1,_xlpm.a="strong",2), _xlpm.y,_xlfn.IFS(_xlpm.b="0",0,_xlpm.b="none",0,_xlpm.b="moderate",1,_xlpm.b="strong",2), _xlpm.d,ABS(_xlpm.x-_xlpm.y), IF(_xlpm.d=0,"green",IF(_xlpm.d=1,"orange",IF(_xlpm.d=2,"red","check"))) )} -> green | EA5: {=_xlfn.LET( _xlpm.a,LOWER(TRIM(DU5&"")), _xlpm.b,LOWER(TRIM(DV5&"")), _xlpm.x,_xlfn.IFS(_xlpm.a="0",0,_xlpm.a="none",0,_xlpm.a="moderate",1,_xlpm.a="strong",2), _xlpm.y,_xlfn.IFS(_xlpm.b="0",0,_xlpm.b="none",0,_xlpm.b="moderate",1,_xlpm.b="strong",2), _xlpm.d,ABS(_xlpm.x-_xlpm.y), IF(_xlpm.d=0,"green",IF(_xlpm.d=1,"orange",IF(_xlpm.d=2,"red","check"))) )} -> green | EB5: {=_xlfn.LET( _xlpm.a,LOWER(TRIM(DW5&"")), _xlpm.b,LOWER(TRIM(DX5&"")), _xlpm.x,_xlfn.IFS(_xlpm.a="0",0,_xlpm.a="none",0,_xlpm.a="moderate",1,_xlpm.a="strong",2), _xlpm.y,_xlfn.IFS(_xlpm.b="0",0,_xlpm.b="none",0,_xlpm.b="moderate",1,_xlpm.b="strong",2), _xlpm.d,ABS(_xlpm.x-_xlpm.y), IF(_xlpm.d=0,"green",IF(_xlpm.d=1,"orange",IF(_xlpm.d=2,"red","check"))) )} -> green | ES5: =IFERROR(VALUE(_xlfn.TEXTBEFORE(_xlfn.TEXTAFTER(AC5,"""84a544d4-0c20-4f9f-bb4b-dd698a9b0c0b"":"),",")),IFERROR(VALUE(_xlfn.TEXTBEFORE(_xlfn.TEXTAFTER(AC5,"""84a544d4-0c20-4f9f-bb4b-dd698a9b0c0b"":"),"}")),IFERROR(VALUE(_xlfn.TEXTBEFORE(_xlfn.TEXTAFTER(AC5,"""784c5905-6667-4dcd-906c-8b405a6572b6"":"),",")),IFERROR(VALUE(_xlfn.TEXTBEFORE(_xlfn.TEXTAFTER(AC5,"""784c5905-6667-4dcd-906c-8b405a6572b6"":"),"}")),"")))) | ET5: =IF(OR(DF5="Strong",DF5="Moderate",DJ5="Strong",DJ5="Moderate",DN5="Strong",DN5="Moderate"),"Yes","No") -> No | EU5: =IF(AND(DE5>=3,DD5=1),"Positive concordance",IF(AND(DE5>=3,DD5>=2),"Gap",IF(AND(DE5<=2,DD5>=2),"Negative concordance","Uninformative"))) -> Uninformative | EV5: =IF(AND(DI5>=3,DH5=1),"Positive concordance",IF(AND(DI5>=3,DH5>=2),"Gap",IF(AND(DI5<=2,DH5>=2),"Negative concordance","Uninformative"))) -> Uninformative | EW5: =IF(AND(DM5>=3,DL5=1),"Positive concordance",IF(AND(DM5>=3,DL5>=2),"Gap",IF(AND(DM5<=2,DL5>=2),"Negative concordance","Uninformative"))) -> Uninformative | EX5: =IF(AND(DE5=4,DD5=1),"Positive concordance",IF(AND(DE5=4,DD5>=2),"Gap",IF(AND(DE5<=3,DD5>=2),"Negative concordance","Uninformative"))) -> Uninformative | EY5: =IF(AND(DI5=4,DH5=1),"Positive concordance",IF(AND(DI5=4,DH5>=2),"Gap",IF(AND(DI5<=3,DH5>=2),"Negative concordance","Uninformative"))) -> Uninformative | EZ5: =IF(AND(DM5=4,DL5=1),"Positive concordance",IF(AND(DM5=4,DL5>=2),"Gap",IF(AND(DM5<=3,DL5>=2),"Negative concordance","Uninformative"))) -> Uninformative | FA5: =IF(OR(EX5="Gap",EY5="Gap",EZ5="Gap"),"Yes","No") -> No
DQ6: =CR6 -> 0 | DR6: =DB6 -> 0 | DS6: =CT6 -> 0 | DT6: =DF6 -> 0 | DU6: =CV6 -> 0 | DV6: =DJ6 -> 0 | DW6: =CX6 -> 0 | DX6: =DN6 -> 0 | DY6: {=_xlfn.LET( _xlpm.a,LOWER(TRIM(DQ6&"")), _xlpm.b,LOWER(TRIM(DR6&"")), _xlpm.x,_xlfn.IFS(_xlpm.a="0",0,_xlpm.a="none",0,_xlpm.a="moderate",1,_xlpm.a="strong",2), _xlpm.y,_xlfn.IFS(_xlpm.b="0",0,_xlpm.b="none",0,_xlpm.b="moderate",1,_xlpm.b="strong",2), _xlpm.d,ABS(_xlpm.x-_xlpm.y), IF(_xlpm.d=0,"green",IF(_xlpm.d=1,"orange",IF(_xlpm.d=2,"red","check"))) )} -> green | DZ6: {=_xlfn.LET( _xlpm.a,LOWER(TRIM(DS6&"")), _xlpm.b,LOWER(TRIM(DT6&"")), _xlpm.x,_xlfn.IFS(_xlpm.a="0",0,_xlpm.a="none",0,_xlpm.a="moderate",1,_xlpm.a="strong",2), _xlpm.y,_xlfn.IFS(_xlpm.b="0",0,_xlpm.b="none",0,_xlpm.b="moderate",1,_xlpm.b="strong",2), _xlpm.d,ABS(_xlpm.x-_xlpm.y), IF(_xlpm.d=0,"green",IF(_xlpm.d=1,"orange",IF(_xlpm.d=2,"red","check"))) )} -> green | EA6: {=_xlfn.LET( _xlpm.a,LOWER(TRIM(DU6&"")), _xlpm.b,LOWER(TRIM(DV6&"")), _xlpm.x,_xlfn.IFS(_xlpm.a="0",0,_xlpm.a="none",0,_xlpm.a="moderate",1,_xlpm.a="strong",2), _xlpm.y,_xlfn.IFS(_xlpm.b="0",0,_xlpm.b="none",0,_xlpm.b="moderate",1,_xlpm.b="strong",2), _xlpm.d,ABS(_xlpm.x-_xlpm.y), IF(_xlpm.d=0,"green",IF(_xlpm.d=1,"orange",IF(_xlpm.d=2,"red","check"))) )} -> green | EB6: {=_xlfn.LET( _xlpm.a,LOWER(TRIM(DW6&"")), _xlpm.b,LOWER(TRIM(DX6&"")), _xlpm.x,_xlfn.IFS(_xlpm.a="0",0,_xlpm.a="none",0,_xlpm.a="moderate",1,_xlpm.a="strong",2), _xlpm.y,_xlfn.IFS(_xlpm.b="0",0,_xlpm.b="none",0,_xlpm.b="moderate",1,_xlpm.b="strong",2), _xlpm.d,ABS(_xlpm.x-_xlpm.y), IF(_xlpm.d=0,"green",IF(_xlpm.d=1,"orange",IF(_xlpm.d=2,"red","check"))) )} -> green | ES6: =IFERROR(VALUE(_xlfn.TEXTBEFORE(_xlfn.TEXTAFTER(AC6,"""84a544d4-0c20-4f9f-bb4b-dd698a9b0c0b"":"),",")),IFERROR(VALUE(_xlfn.TEXTBEFORE(_xlfn.TEXTAFTER(AC6,"""84a544d4-0c20-4f9f-bb4b-dd698a9b0c0b"":"),"}")),IFERROR(VALUE(_xlfn.TEXTBEFORE(_xlfn.TEXTAFTER(AC6,"""784c5905-6667-4dcd-906c-8b405a6572b6"":"),",")),IFERROR(VALUE(_xlfn.TEXTBEFORE(_xlfn.TEXTAFTER(AC6,"""784c5905-6667-4dcd-906c-8b405a6572b6"":"),"}")),"")))) | ET6: =IF(OR(DF6="Strong",DF6="Moderate",DJ6="Strong",DJ6="Moderate",DN6="Strong",DN6="Moderate"),"Yes","No") -> No | EU6: =IF(AND(DE6>=3,DD6=1),"Positive concordance",IF(AND(DE6>=3,DD6>=2),"Gap",IF(AND(DE6<=2,DD6>=2),"Negative concordance","Uninformative"))) -> Uninformative | EV6: =IF(AND(DI6>=3,DH6=1),"Positive concordance",IF(AND(DI6>=3,DH6>=2),"Gap",IF(AND(DI6<=2,DH6>=2),"Negative concordance","Uninformative"))) -> Uninformative | EW6: =IF(AND(DM6>=3,DL6=1),"Positive concordance",IF(AND(DM6>=3,DL6>=2),"Gap",IF(AND(DM6<=2,DL6>=2),"Negative concordance","Uninformative"))) -> Uninformative | EX6: =IF(AND(DE6=4,DD6=1),"Positive concordance",IF(AND(DE6=4,DD6>=2),"Gap",IF(AND(DE6<=3,DD6>=2),"Negative concordance","Uninformative"))) -> Uninformative | EY6: =IF(AND(DI6=4,DH6=1),"Positive concordance",IF(AND(DI6=4,DH6>=2),"Gap",IF(AND(DI6<=3,DH6>=2),"Negative concordance","Uninformative"))) -> Uninformative | EZ6: =IF(AND(DM6=4,DL6=1),"Positive concordance",IF(AND(DM6=4,DL6>=2),"Gap",IF(AND(DM6<=3,DL6>=2),"Negative concordance","Uninformative"))) -> Uninformative | FA6: =IF(OR(EX6="Gap",EY6="Gap",EZ6="Gap"),"Yes","No") -> No
DQ7: =CR7 -> 0 | DR7: =DB7 -> 0 | DS7: =CT7 -> 0 | DT7: =DF7 -> 0 | DU7: =CV7 -> 0 | DV7: =DJ7 -> 0 | DW7: =CX7 -> 0 | DX7: =DN7 -> 0 | DY7: {=_xlfn.LET( _xlpm.a,LOWER(TRIM(DQ7&"")), _xlpm.b,LOWER(TRIM(DR7&"")), _xlpm.x,_xlfn.IFS(_xlpm.a="0",0,_xlpm.a="none",0,_xlpm.a="moderate",1,_xlpm.a="strong",2), _xlpm.y,_xlfn.IFS(_xlpm.b="0",0,_xlpm.b="none",0,_xlpm.b="moderate",1,_xlpm.b="strong",2), _xlpm.d,ABS(_xlpm.x-_xlpm.y), IF(_xlpm.d=0,"green",IF(_xlpm.d=1,"orange",IF(_xlpm.d=2,"red","check"))) )} -> green | DZ7: {=_xlfn.LET( _xlpm.a,LOWER(TRIM(DS7&"")), _xlpm.b,LOWER(TRIM(DT7&"")), _xlpm.x,_xlfn.IFS(_xlpm.a="0",0,_xlpm.a="none",0,_xlpm.a="moderate",1,_xlpm.a="strong",2), _xlpm.y,_xlfn.IFS(_xlpm.b="0",0,_xlpm.b="none",0,_xlpm.b="moderate",1,_xlpm.b="strong",2), _xlpm.d,ABS(_xlpm.x-_xlpm.y), IF(_xlpm.d=0,"green",IF(_xlpm.d=1,"orange",IF(_xlpm.d=2,"red","check"))) )} -> green | EA7: {=_xlfn.LET( _xlpm.a,LOWER(TRIM(DU7&"")), _xlpm.b,LOWER(TRIM(DV7&"")), _xlpm.x,_xlfn.IFS(_xlpm.a="0",0,_xlpm.a="none",0,_xlpm.a="moderate",1,_xlpm.a="strong",2), _xlpm.y,_xlfn.IFS(_xlpm.b="0",0,_xlpm.b="none",0,_xlpm.b="moderate",1,_xlpm.b="strong",2), _xlpm.d,ABS(_xlpm.x-_xlpm.y), IF(_xlpm.d=0,"green",IF(_xlpm.d=1,"orange",IF(_xlpm.d=2,"red","check"))) )} -> green | EB7: {=_xlfn.LET( _xlpm.a,LOWER(TRIM(DW7&"")), _xlpm.b,LOWER(TRIM(DX7&"")), _xlpm.x,_xlfn.IFS(_xlpm.a="0",0,_xlpm.a="none",0,_xlpm.a="moderate",1,_xlpm.a="strong",2), _xlpm.y,_xlfn.IFS(_xlpm.b="0",0,_xlpm.b="none",0,_xlpm.b="moderate",1,_xlpm.b="strong",2), _xlpm.d,ABS(_xlpm.x-_xlpm.y), IF(_xlpm.d=0,"green",IF(_xlpm.d=1,"orange",IF(_xlpm.d=2,"red","check"))) )} -> green | ES7: =IFERROR(VALUE(_xlfn.TEXTBEFORE(_xlfn.TEXTAFTER(AC7,"""84a544d4-0c20-4f9f-bb4b-dd698a9b0c0b"":"),",")),IFERROR(VALUE(_xlfn.TEXTBEFORE(_xlfn.TEXTAFTER(AC7,"""84a544d4-0c20-4f9f-bb4b-dd698a9b0c0b"":"),"}")),IFERROR(VALUE(_xlfn.TEXTBEFORE(_xlfn.TEXTAFTER(AC7,"""784c5905-6667-4dcd-906c-8b405a6572b6"":"),",")),IFERROR(VALUE(_xlfn.TEXTBEFORE(_xlfn.TEXTAFTER(AC7,"""784c5905-6667-4dcd-906c-8b405a6572b6"":"),"}")),"")))) | ET7: =IF(OR(DF7="Strong",DF7="Moderate",DJ7="Strong",DJ7="Moderate",DN7="Strong",DN7="Moderate"),"Yes","No") -> No | EU7: =IF(AND(DE7>=3,DD7=1),"Positive concordance",IF(AND(DE7>=3,DD7>=2),"Gap",IF(AND(DE7<=2,DD7>=2),"Negative concordance","Uninformative"))) -> Uninformative | EV7: =IF(AND(DI7>=3,DH7=1),"Positive concordance",IF(AND(DI7>=3,DH7>=2),"Gap",IF(AND(DI7<=2,DH7>=2),"Negative concordance","Uninformative"))) -> Uninformative | EW7: =IF(AND(DM7>=3,DL7=1),"Positive concordance",IF(AND(DM7>=3,DL7>=2),"Gap",IF(AND(DM7<=2,DL7>=2),"Negative concordance","Uninformative"))) -> Uninformative | EX7: =IF(AND(DE7=4,DD7=1),"Positive concordance",IF(AND(DE7=4,DD7>=2),"Gap",IF(AND(DE7<=3,DD7>=2),"Negative concordance","Uninformative"))) -> Uninformative | EY7: =IF(AND(DI7=4,DH7=1),"Positive concordance",IF(AND(DI7=4,DH7>=2),"Gap",IF(AND(DI7<=3,DH7>=2),"Negative concordance","Uninformative"))) -> Uninformative | EZ7: =IF(AND(DM7=4,DL7=1),"Positive concordance",IF(AND(DM7=4,DL7>=2),"Gap",IF(AND(DM7<=3,DL7>=2),"Negative concordance","Uninformative"))) -> Uninformative | FA7: =IF(OR(EX7="Gap",EY7="Gap",EZ7="Gap"),"Yes","No") -> No
DQ8: =CR8 -> 0 | DR8: =DB8 -> 0 | DS8: =CT8 -> 0 | DT8: =DF8 -> 0 | DU8: =CV8 -> 0 | DV8: =DJ8 -> 0 | DW8: =CX8 -> 0 | DX8: =DN8 -> 0 | DY8: {=_xlfn.LET( _xlpm.a,LOWER(TRIM(DQ8&"")), _xlpm.b,LOWER(TRIM(DR8&"")), _xlpm.x,_xlfn.IFS(_xlpm.a="0",0,_xlpm.a="none",0,_xlpm.a="moderate",1,_xlpm.a="strong",2), _xlpm.y,_xlfn.IFS(_xlpm.b="0",0,_xlpm.b="none",0,_xlpm.b="moderate",1,_xlpm.b="strong",2), _xlpm.d,ABS(_xlpm.x-_xlpm.y), IF(_xlpm.d=0,"green",IF(_xlpm.d=1,"orange",IF(_xlpm.d=2,"red","check"))) )} -> green | DZ8: {=_xlfn.LET( _xlpm.a,LOWER(TRIM(DS8&"")), _xlpm.b,LOWER(TRIM(DT8&"")), _xlpm.x,_xlfn.IFS(_xlpm.a="0",0,_xlpm.a="none",0,_xlpm.a="moderate",1,_xlpm.a="strong",2), _xlpm.y,_xlfn.IFS(_xlpm.b="0",0,_xlpm.b="none",0,_xlpm.b="moderate",1,_xlpm.b="strong",2), _xlpm.d,ABS(_xlpm.x-_xlpm.y), IF(_xlpm.d=0,"green",IF(_xlpm.d=1,"orange",IF(_xlpm.d=2,"red","check"))) )} -> green | EA8: {=_xlfn.LET( _xlpm.a,LOWER(TRIM(DU8&"")), _xlpm.b,LOWER(TRIM(DV8&"")), _xlpm.x,_xlfn.IFS(_xlpm.a="0",0,_xlpm.a="none",0,_xlpm.a="moderate",1,_xlpm.a="strong",2), _xlpm.y,_xlfn.IFS(_xlpm.b="0",0,_xlpm.b="none",0,_xlpm.b="moderate",1,_xlpm.b="strong",2), _xlpm.d,ABS(_xlpm.x-_xlpm.y), IF(_xlpm.d=0,"green",IF(_xlpm.d=1,"orange",IF(_xlpm.d=2,"red","check"))) )} -> green | EB8: {=_xlfn.LET( _xlpm.a,LOWER(TRIM(DW8&"")), _xlpm.b,LOWER(TRIM(DX8&"")), _xlpm.x,_xlfn.IFS(_xlpm.a="0",0,_xlpm.a="none",0,_xlpm.a="moderate",1,_xlpm.a="strong",2), _xlpm.y,_xlfn.IFS(_xlpm.b="0",0,_xlpm.b="none",0,_xlpm.b="moderate",1,_xlpm.b="strong",2), _xlpm.d,ABS(_xlpm.x-_xlpm.y), IF(_xlpm.d=0,"green",IF(_xlpm.d=1,"orange",IF(_xlpm.d=2,"red","check"))) )} -> green | ES8: =IFERROR(VALUE(_xlfn.TEXTBEFORE(_xlfn.TEXTAFTER(AC8,"""84a544d4-0c20-4f9f-bb4b-dd698a9b0c0b"":"),",")),IFERROR(VALUE(_xlfn.TEXTBEFORE(_xlfn.TEXTAFTER(AC8,"""84a544d4-0c20-4f9f-bb4b-dd698a9b0c0b"":"),"}")),IFERROR(VALUE(_xlfn.TEXTBEFORE(_xlfn.TEXTAFTER(AC8,"""784c5905-6667-4dcd-906c-8b405a6572b6"":"),",")),IFERROR(VALUE(_xlfn.TEXTBEFORE(_xlfn.TEXTAFTER(AC8,"""784c5905-6667-4dcd-906c-8b405a6572b6"":"),"}")),"")))) | ET8: =IF(OR(DF8="Strong",DF8="Moderate",DJ8="Strong",DJ8="Moderate",DN8="Strong",DN8="Moderate"),"Yes","No") -> No | EU8: =IF(AND(DE8>=3,DD8=1),"Positive concordance",IF(AND(DE8>=3,DD8>=2),"Gap",IF(AND(DE8<=2,DD8>=2),"Negative concordance","Uninformative"))) -> Uninformative | EV8: =IF(AND(DI8>=3,DH8=1),"Positive concordance",IF(AND(DI8>=3,DH8>=2),"Gap",IF(AND(DI8<=2,DH8>=2),"Negative concordance","Uninformative"))) -> Uninformative | EW8: =IF(AND(DM8>=3,DL8=1),"Positive concordance",IF(AND(DM8>=3,DL8>=2),"Gap",IF(AND(DM8<=2,DL8>=2),"Negative concordance","Uninformative"))) -> Uninformative | EX8: =IF(AND(DE8=4,DD8=1),"Positive concordance",IF(AND(DE8=4,DD8>=2),"Gap",IF(AND(DE8<=3,DD8>=2),"Negative concordance","Uninformative"))) -> Uninformative | EY8: =IF(AND(DI8=4,DH8=1),"Positive concordance",IF(AND(DI8=4,DH8>=2),"Gap",IF(AND(DI8<=3,DH8>=2),"Negative concordance","Uninformative"))) -> Uninformative | EZ8: =IF(AND(DM8=4,DL8=1),"Positive concordance",IF(AND(DM8=4,DL8>=2),"Gap",IF(AND(DM8<=3,DL8>=2),"Negative concordance","Uninformative"))) -> Uninformative | FA8: =IF(OR(EX8="Gap",EY8="Gap",EZ8="Gap"),"Yes","No") -> No
DQ9: =CR9 -> 0 | DR9: =DB9 -> 0 | DS9: =CT9 -> 0 | DT9: =DF9 -> 0 | DU9: =CV9 -> 0 | DV9: =DJ9 -> 0 | DW9: =CX9 -> 0 | DX9: =DN9 -> 0 | DY9: {=_xlfn.LET( _xlpm.a,LOWER(TRIM(DQ9&"")), _xlpm.b,LOWER(TRIM(DR9&"")), _xlpm.x,_xlfn.IFS(_xlpm.a="0",0,_xlpm.a="none",0,_xlpm.a="moderate",1,_xlpm.a="strong",2), _xlpm.y,_xlfn.IFS(_xlpm.b="0",0,_xlpm.b="none",0,_xlpm.b="moderate",1,_xlpm.b="strong",2), _xlpm.d,ABS(_xlpm.x-_xlpm.y), IF(_xlpm.d=0,"green",IF(_xlpm.d=1,"orange",IF(_xlpm.d=2,"red","check"))) )} -> green | DZ9: {=_xlfn.LET( _xlpm.a,LOWER(TRIM(DS9&"")), _xlpm.b,LOWER(TRIM(DT9&"")), _xlpm.x,_xlfn.IFS(_xlpm.a="0",0,_xlpm.a="none",0,_xlpm.a="moderate",1,_xlpm.a="strong",2), _xlpm.y,_xlfn.IFS(_xlpm.b="0",0,_xlpm.b="none",0,_xlpm.b="moderate",1,_xlpm.b="strong",2), _xlpm.d,ABS(_xlpm.x-_xlpm.y), IF(_xlpm.d=0,"green",IF(_xlpm.d=1,"orange",IF(_xlpm.d=2,"red","check"))) )} -> green | EA9: {=_xlfn.LET( _xlpm.a,LOWER(TRIM(DU9&"")), _xlpm.b,LOWER(TRIM(DV9&"")), _xlpm.x,_xlfn.IFS(_xlpm.a="0",0,_xlpm.a="none",0,_xlpm.a="moderate",1,_xlpm.a="strong",2), _xlpm.y,_xlfn.IFS(_xlpm.b="0",0,_xlpm.b="none",0,_xlpm.b="moderate",1,_xlpm.b="strong",2), _xlpm.d,ABS(_xlpm.x-_xlpm.y), IF(_xlpm.d=0,"green",IF(_xlpm.d=1,"orange",IF(_xlpm.d=2,"red","check"))) )} -> green | EB9: {=_xlfn.LET( _xlpm.a,LOWER(TRIM(DW9&"")), _xlpm.b,LOWER(TRIM(DX9&"")), _xlpm.x,_xlfn.IFS(_xlpm.a="0",0,_xlpm.a="none",0,_xlpm.a="moderate",1,_xlpm.a="strong",2), _xlpm.y,_xlfn.IFS(_xlpm.b="0",0,_xlpm.b="none",0,_xlpm.b="moderate",1,_xlpm.b="strong",2), _xlpm.d,ABS(_xlpm.x-_xlpm.y), IF(_xlpm.d=0,"green",IF(_xlpm.d=1,"orange",IF(_xlpm.d=2,"red","check"))) )} -> green | ES9: =IFERROR(VALUE(_xlfn.TEXTBEFORE(_xlfn.TEXTAFTER(AC9,"""84a544d4-0c20-4f9f-bb4b-dd698a9b0c0b"":"),",")),IFERROR(VALUE(_xlfn.TEXTBEFORE(_xlfn.TEXTAFTER(AC9,"""84a544d4-0c20-4f9f-bb4b-dd698a9b0c0b"":"),"}")),IFERROR(VALUE(_xlfn.TEXTBEFORE(_xlfn.TEXTAFTER(AC9,"""784c5905-6667-4dcd-906c-8b405a6572b6"":"),",")),IFERROR(VALUE(_xlfn.TEXTBEFORE(_xlfn.TEXTAFTER(AC9,"""784c5905-6667-4dcd-906c-8b405a6572b6"":"),"}")),"")))) | ET9: =IF(OR(DF9="Strong",DF9="Moderate",DJ9="Strong",DJ9="Moderate",DN9="Strong",DN9="Moderate"),"Yes","No") -> No | EU9: =IF(AND(DE9>=3,DD9=1),"Positive concordance",IF(AND(DE9>=3,DD9>=2),"Gap",IF(AND(DE9<=2,DD9>=2),"Negative concordance","Uninformative"))) -> Uninformative | EV9: =IF(AND(DI9>=3,DH9=1),"Positive concordance",IF(AND(DI9>=3,DH9>=2),"Gap",IF(AND(DI9<=2,DH9>=2),"Negative concordance","Uninformative"))) -> Uninformative | EW9: =IF(AND(DM9>=3,DL9=1),"Positive concordance",IF(AND(DM9>=3,DL9>=2),"Gap",IF(AND(DM9<=2,DL9>=2),"Negative concordance","Uninformative"))) -> Uninformative | EX9: =IF(AND(DE9=4,DD9=1),"Positive concordance",IF(AND(DE9=4,DD9>=2),"Gap",IF(AND(DE9<=3,DD9>=2),"Negative concordance","Uninformative"))) -> Uninformative | EY9: =IF(AND(DI9=4,DH9=1),"Positive concordance",IF(AND(DI9=4,DH9>=2),"Gap",IF(AND(DI9<=3,DH9>=2),"Negative concordance","Uninformative"))) -> Uninformative | EZ9: =IF(AND(DM9=4,DL9=1),"Positive concordance",IF(AND(DM9=4,DL9>=2),"Gap",IF(AND(DM9<=3,DL9>=2),"Negative concordance","Uninformative"))) -> Uninformative | FA9: =IF(OR(EX9="Gap",EY9="Gap",EZ9="Gap"),"Yes","No") -> No
DQ10: =CR10 -> 0 | DR10: =DB10 -> 0 | DS10: =CT10 -> 0 | DT10: =DF10 -> 0 | DU10: =CV10 -> 0 | DV10: =DJ10 -> 0 | DW10: =CX10 -> 0 | DX10: =DN10 -> 0 | DY10: {=_xlfn.LET( _xlpm.a,LOWER(TRIM(DQ10&"")), _xlpm.b,LOWER(TRIM(DR10&"")), _xlpm.x,_xlfn.IFS(_xlpm.a="0",0,_xlpm.a="none",0,_xlpm.a="moderate",1,_xlpm.a="strong",2), _xlpm.y,_xlfn.IFS(_xlpm.b="0",0,_xlpm.b="none",0,_xlpm.b="moderate",1,_xlpm.b="strong",2), _xlpm.d,ABS(_xlpm.x-_xlpm.y), IF(_xlpm.d=0,"green",IF(_xlpm.d=1,"orange",IF(_xlpm.d=2,"red","check"))) )} -> green | DZ10: {=_xlfn.LET( _xlpm.a,LOWER(TRIM(DS10&"")), _xlpm.b,LOWER(TRIM(DT10&"")), _xlpm.x,_xlfn.IFS(_xlpm.a="0",0,_xlpm.a="none",0,_xlpm.a="moderate",1,_xlpm.a="strong",2), _xlpm.y,_xlfn.IFS(_xlpm.b="0",0,_xlpm.b="none",0,_xlpm.b="moderate",1,_xlpm.b="strong",2), _xlpm.d,ABS(_xlpm.x-_xlpm.y), IF(_xlpm.d=0,"green",IF(_xlpm.d=1,"orange",IF(_xlpm.d=2,"red","check"))) )} -> green | EA10: {=_xlfn.LET( _xlpm.a,LOWER(TRIM(DU10&"")), _xlpm.b,LOWER(TRIM(DV10&"")), _xlpm.x,_xlfn.IFS(_xlpm.a="0",0,_xlpm.a="none",0,_xlpm.a="moderate",1,_xlpm.a="strong",2), _xlpm.y,_xlfn.IFS(_xlpm.b="0",0,_xlpm.b="none",0,_xlpm.b="moderate",1,_xlpm.b="strong",2), _xlpm.d,ABS(_xlpm.x-_xlpm.y), IF(_xlpm.d=0,"green",IF(_xlpm.d=1,"orange",IF(_xlpm.d=2,"red","check"))) )} -> green | EB10: {=_xlfn.LET( _xlpm.a,LOWER(TRIM(DW10&"")), _xlpm.b,LOWER(TRIM(DX10&"")), _xlpm.x,_xlfn.IFS(_xlpm.a="0",0,_xlpm.a="none",0,_xlpm.a="moderate",1,_xlpm.a="strong",2), _xlpm.y,_xlfn.IFS(_xlpm.b="0",0,_xlpm.b="none",0,_xlpm.b="moderate",1,_xlpm.b="strong",2), _xlpm.d,ABS(_xlpm.x-_xlpm.y), IF(_xlpm.d=0,"green",IF(_xlpm.d=1,"orange",IF(_xlpm.d=2,"red","check"))) )} -> green | ES10: =IFERROR(VALUE(_xlfn.TEXTBEFORE(_xlfn.TEXTAFTER(AC10,"""84a544d4-0c20-4f9f-bb4b-dd698a9b0c0b"":"),",")),IFERROR(VALUE(_xlfn.TEXTBEFORE(_xlfn.TEXTAFTER(AC10,"""84a544d4-0c20-4f9f-bb4b-dd698a9b0c0b"":"),"}")),IFERROR(VALUE(_xlfn.TEXTBEFORE(_xlfn.TEXTAFTER(AC10,"""784c5905-6667-4dcd-906c-8b405a6572b6"":"),",")),IFERROR(VALUE(_xlfn.TEXTBEFORE(_xlfn.TEXTAFTER(AC10,"""784c5905-6667-4dcd-906c-8b405a6572b6"":"),"}")),"")))) | ET10: =IF(OR(DF10="Strong",DF10="Moderate",DJ10="Strong",DJ10="Moderate",DN10="Strong",DN10="Moderate"),"Yes","No") -> No | EU10: =IF(AND(DE10>=3,DD10=1),"Positive concordance",IF(AND(DE10>=3,DD10>=2),"Gap",IF(AND(DE10<=2,DD10>=2),"Negative concordance","Uninformative"))) -> Uninformative | EV10: =IF(AND(DI10>=3,DH10=1),"Positive concordance",IF(AND(DI10>=3,DH10>=2),"Gap",IF(AND(DI10<=2,DH10>=2),"Negative concordance","Uninformative"))) -> Uninformative | EW10: =IF(AND(DM10>=3,DL10=1),"Positive concordance",IF(AND(DM10>=3,DL10>=2),"Gap",IF(AND(DM10<=2,DL10>=2),"Negative concordance","Uninformative"))) -> Uninformative | EX10: =IF(AND(DE10=4,DD10=1),"Positive concordance",IF(AND(DE10=4,DD10>=2),"Gap",IF(AND(DE10<=3,DD10>=2),"Negative concordance","Uninformative"))) -> Uninformative | EY10: =IF(AND(DI10=4,DH10=1),"Positive concordance",IF(AND(DI10=4,DH10>=2),"Gap",IF(AND(DI10<=3,DH10>=2),"Negative concordance","Uninformative"))) -> Uninformative | EZ10: =IF(AND(DM10=4,DL10=1),"Positive concordance",IF(AND(DM10=4,DL10>=2),"Gap",IF(AND(DM10<=3,DL10>=2),"Negative concordance","Uninformative"))) -> Uninformative | FA10: =IF(OR(EX10="Gap",EY10="Gap",EZ10="Gap"),"Yes","No") -> No
DQ11: =CR11 -> 0 | DR11: =DB11 -> 0 | DS11: =CT11 -> 0 | DT11: =DF11 -> 0 | DU11: =CV11 -> 0 | DV11: =DJ11 -> 0 | DW11: =CX11 -> 0 | DX11: =DN11 -> 0 | DY11: {=_xlfn.LET( _xlpm.a,LOWER(TRIM(DQ11&"")), _xlpm.b,LOWER(TRIM(DR11&"")), _xlpm.x,_xlfn.IFS(_xlpm.a="0",0,_xlpm.a="none",0,_xlpm.a="moderate",1,_xlpm.a="strong",2), _xlpm.y,_xlfn.IFS(_xlpm.b="0",0,_xlpm.b="none",0,_xlpm.b="moderate",1,_xlpm.b="strong",2), _xlpm.d,ABS(_xlpm.x-_xlpm.y), IF(_xlpm.d=0,"green",IF(_xlpm.d=1,"orange",IF(_xlpm.d=2,"red","check"))) )} -> green | DZ11: {=_xlfn.LET( _xlpm.a,LOWER(TRIM(DS11&"")), _xlpm.b,LOWER(TRIM(DT11&"")), _xlpm.x,_xlfn.IFS(_xlpm.a="0",0,_xlpm.a="none",0,_xlpm.a="moderate",1,_xlpm.a="strong",2), _xlpm.y,_xlfn.IFS(_xlpm.b="0",0,_xlpm.b="none",0,_xlpm.b="moderate",1,_xlpm.b="strong",2), _xlpm.d,ABS(_xlpm.x-_xlpm.y), IF(_xlpm.d=0,"green",IF(_xlpm.d=1,"orange",IF(_xlpm.d=2,"red","check"))) )} -> green | EA11: {=_xlfn.LET( _xlpm.a,LOWER(TRIM(DU11&"")), _xlpm.b,LOWER(TRIM(DV11&"")), _xlpm.x,_xlfn.IFS(_xlpm.a="0",0,_xlpm.a="none",0,_xlpm.a="moderate",1,_xlpm.a="strong",2), _xlpm.y,_xlfn.IFS(_xlpm.b="0",0,_xlpm.b="none",0,_xlpm.b="moderate",1,_xlpm.b="strong",2), _xlpm.d,ABS(_xlpm.x-_xlpm.y), IF(_xlpm.d=0,"green",IF(_xlpm.d=1,"orange",IF(_xlpm.d=2,"red","check"))) )} -> green | EB11: {=_xlfn.LET( _xlpm.a,LOWER(TRIM(DW11&"")), _xlpm.b,LOWER(TRIM(DX11&"")), _xlpm.x,_xlfn.IFS(_xlpm.a="0",0,_xlpm.a="none",0,_xlpm.a="moderate",1,_xlpm.a="strong",2), _xlpm.y,_xlfn.IFS(_xlpm.b="0",0,_xlpm.b="none",0,_xlpm.b="moderate",1,_xlpm.b="strong",2), _xlpm.d,ABS(_xlpm.x-_xlpm.y), IF(_xlpm.d=0,"green",IF(_xlpm.d=1,"orange",IF(_xlpm.d=2,"red","check"))) )} -> green | ES11: =IFERROR(VALUE(_xlfn.TEXTBEFORE(_xlfn.TEXTAFTER(AC11,"""84a544d4-0c20-4f9f-bb4b-dd698a9b0c0b"":"),",")),IFERROR(VALUE(_xlfn.TEXTBEFORE(_xlfn.TEXTAFTER(AC11,"""84a544d4-0c20-4f9f-bb4b-dd698a9b0c0b"":"),"}")),IFERROR(VALUE(_xlfn.TEXTBEFORE(_xlfn.TEXTAFTER(AC11,"""784c5905-6667-4dcd-906c-8b405a6572b6"":"),",")),IFERROR(VALUE(_xlfn.TEXTBEFORE(_xlfn.TEXTAFTER(AC11,"""784c5905-6667-4dcd-906c-8b405a6572b6"":"),"}")),"")))) | ET11: =IF(OR(DF11="Strong",DF11="Moderate",DJ11="Strong",DJ11="Moderate",DN11="Strong",DN11="Moderate"),"Yes","No") -> No | EU11: =IF(AND(DE11>=3,DD11=1),"Positive concordance",IF(AND(DE11>=3,DD11>=2),"Gap",IF(AND(DE11<=2,DD11>=2),"Negative concordance","Uninformative"))) -> Uninformative | EV11: =IF(AND(DI11>=3,DH11=1),"Positive concordance",IF(AND(DI11>=3,DH11>=2),"Gap",IF(AND(DI11<=2,DH11>=2),"Negative concordance","Uninformative"))) -> Uninformative | EW11: =IF(AND(DM11>=3,DL11=1),"Positive concordance",IF(AND(DM11>=3,DL11>=2),"Gap",IF(AND(DM11<=2,DL11>=2),"Negative concordance","Uninformative"))) -> Uninformative | EX11: =IF(AND(DE11=4,DD11=1),"Positive concordance",IF(AND(DE11=4,DD11>=2),"Gap",IF(AND(DE11<=3,DD11>=2),"Negative concordance","Uninformative"))) -> Uninformative | EY11: =IF(AND(DI11=4,DH11=1),"Positive concordance",IF(AND(DI11=4,DH11>=2),"Gap",IF(AND(DI11<=3,DH11>=2),"Negative concordance","Uninformative"))) -> Uninformative | EZ11: =IF(AND(DM11=4,DL11=1),"Positive concordance",IF(AND(DM11=4,DL11>=2),"Gap",IF(AND(DM11<=3,DL11>=2),"Negative concordance","Uninformative"))) -> Uninformative | FA11: =IF(OR(EX11="Gap",EY11="Gap",EZ11="Gap"),"Yes","No") -> No
DQ12: =CR12 -> 0 | DR12: =DB12 -> 0 | DS12: =CT12 -> 0 | DT12: =DF12 -> 0 | DU12: =CV12 -> 0 | DV12: =DJ12 -> 0 | DW12: =CX12 -> 0 | DX12: =DN12 -> 0 | DY12: {=_xlfn.LET( _xlpm.a,LOWER(TRIM(DQ12&"")), _xlpm.b,LOWER(TRIM(DR12&"")), _xlpm.x,_xlfn.IFS(_xlpm.a="0",0,_xlpm.a="none",0,_xlpm.a="moderate",1,_xlpm.a="strong",2), _xlpm.y,_xlfn.IFS(_xlpm.b="0",0,_xlpm.b="none",0,_xlpm.b="moderate",1,_xlpm.b="strong",2), _xlpm.d,ABS(_xlpm.x-_xlpm.y), IF(_xlpm.d=0,"green",IF(_xlpm.d=1,"orange",IF(_xlpm.d=2,"red","check"))) )} -> green | DZ12: {=_xlfn.LET( _xlpm.a,LOWER(TRIM(DS12&"")), _xlpm.b,LOWER(TRIM(DT12&"")), _xlpm.x,_xlfn.IFS(_xlpm.a="0",0,_xlpm.a="none",0,_xlpm.a="moderate",1,_xlpm.a="strong",2), _xlpm.y,_xlfn.IFS(_xlpm.b="0",0,_xlpm.b="none",0,_xlpm.b="moderate",1,_xlpm.b="strong",2), _xlpm.d,ABS(_xlpm.x-_xlpm.y), IF(_xlpm.d=0,"green",IF(_xlpm.d=1,"orange",IF(_xlpm.d=2,"red","check"))) )} -> green | EA12: {=_xlfn.LET( _xlpm.a,LOWER(TRIM(DU12&"")), _xlpm.b,LOWER(TRIM(DV12&"")), _xlpm.x,_xlfn.IFS(_xlpm.a="0",0,_xlpm.a="none",0,_xlpm.a="moderate",1,_xlpm.a="strong",2), _xlpm.y,_xlfn.IFS(_xlpm.b="0",0,_xlpm.b="none",0,_xlpm.b="moderate",1,_xlpm.b="strong",2), _xlpm.d,ABS(_xlpm.x-_xlpm.y), IF(_xlpm.d=0,"green",IF(_xlpm.d=1,"orange",IF(_xlpm.d=2,"red","check"))) )} -> green | EB12: {=_xlfn.LET( _xlpm.a,LOWER(TRIM(DW12&"")), _xlpm.b,LOWER(TRIM(DX12&"")), _xlpm.x,_xlfn.IFS(_xlpm.a="0",0,_xlpm.a="none",0,_xlpm.a="moderate",1,_xlpm.a="strong",2), _xlpm.y,_xlfn.IFS(_xlpm.b="0",0,_xlpm.b="none",0,_xlpm.b="moderate",1,_xlpm.b="strong",2), _xlpm.d,ABS(_xlpm.x-_xlpm.y), IF(_xlpm.d=0,"green",IF(_xlpm.d=1,"orange",IF(_xlpm.d=2,"red","check"))) )} -> green | ES12: =IFERROR(VALUE(_xlfn.TEXTBEFORE(_xlfn.TEXTAFTER(AC12,"""84a544d4-0c20-4f9f-bb4b-dd698a9b0c0b"":"),",")),IFERROR(VALUE(_xlfn.TEXTBEFORE(_xlfn.TEXTAFTER(AC12,"""84a544d4-0c20-4f9f-bb4b-dd698a9b0c0b"":"),"}")),IFERROR(VALUE(_xlfn.TEXTBEFORE(_xlfn.TEXTAFTER(AC12,"""784c5905-6667-4dcd-906c-8b405a6572b6"":"),",")),IFERROR(VALUE(_xlfn.TEXTBEFORE(_xlfn.TEXTAFTER(AC12,"""784c5905-6667-4dcd-906c-8b405a6572b6"":"),"}")),"")))) | ET12: =IF(OR(DF12="Strong",DF12="Moderate",DJ12="Strong",DJ12="Moderate",DN12="Strong",DN12="Moderate"),"Yes","No") -> No | EU12: =IF(AND(DE12>=3,DD12=1),"Positive concordance",IF(AND(DE12>=3,DD12>=2),"Gap",IF(AND(DE12<=2,DD12>=2),"Negative concordance","Uninformative"))) -> Uninformative | EV12: =IF(AND(DI12>=3,DH12=1),"Positive concordance",IF(AND(DI12>=3,DH12>=2),"Gap",IF(AND(DI12<=2,DH12>=2),"Negative concordance","Uninformative"))) -> Uninformative | EW12: =IF(AND(DM12>=3,DL12=1),"Positive concordance",IF(AND(DM12>=3,DL12>=2),"Gap",IF(AND(DM12<=2,DL12>=2),"Negative concordance","Uninformative"))) -> Uninformative | EX12: =IF(AND(DE12=4,DD12=1),"Positive concordance",IF(AND(DE12=4,DD12>=2),"Gap",IF(AND(DE12<=3,DD12>=2),"Negative concordance","Uninformative"))) -> Uninformative | EY12: =IF(AND(DI12=4,DH12=1),"Positive concordance",IF(AND(DI12=4,DH12>=2),"Gap",IF(AND(DI12<=3,DH12>=2),"Negative concordance","Uninformative"))) -> Uninformative | EZ12: =IF(AND(DM12=4,DL12=1),"Positive concordance",IF(AND(DM12=4,DL12>=2),"Gap",IF(AND(DM12<=3,DL12>=2),"Negative concordance","Uninformative"))) -> Uninformative | FA12: =IF(OR(EX12="Gap",EY12="Gap",EZ12="Gap"),"Yes","No") -> No
DQ13: =CR13 -> 0 | DR13: =DB13 -> 0 | DS13: =CT13 -> 0 | DT13: =DF13 -> 0 | DU13: =CV13 -> 0 | DV13: =DJ13 -> 0 | DW13: =CX13 -> 0 | DX13: =DN13 -> 0 | DY13: {=_xlfn.LET( _xlpm.a,LOWER(TRIM(DQ13&"")), _xlpm.b,LOWER(TRIM(DR13&"")), _xlpm.x,_xlfn.IFS(_xlpm.a="0",0,_xlpm.a="none",0,_xlpm.a="moderate",1,_xlpm.a="strong",2), _xlpm.y,_xlfn.IFS(_xlpm.b="0",0,_xlpm.b="none",0,_xlpm.b="moderate",1,_xlpm.b="strong",2), _xlpm.d,ABS(_xlpm.x-_xlpm.y), IF(_xlpm.d=0,"green",IF(_xlpm.d=1,"orange",IF(_xlpm.d=2,"red","check"))) )} -> green | DZ13: {=_xlfn.LET( _xlpm.a,LOWER(TRIM(DS13&"")), _xlpm.b,LOWER(TRIM(DT13&"")), _xlpm.x,_xlfn.IFS(_xlpm.a="0",0,_xlpm.a="none",0,_xlpm.a="moderate",1,_xlpm.a="strong",2), _xlpm.y,_xlfn.IFS(_xlpm.b="0",0,_xlpm.b="none",0,_xlpm.b="moderate",1,_xlpm.b="strong",2), _xlpm.d,ABS(_xlpm.x-_xlpm.y), IF(_xlpm.d=0,"green",IF(_xlpm.d=1,"orange",IF(_xlpm.d=2,"red","check"))) )} -> green | EA13: {=_xlfn.LET( _xlpm.a,LOWER(TRIM(DU13&"")), _xlpm.b,LOWER(TRIM(DV13&"")), _xlpm.x,_xlfn.IFS(_xlpm.a="0",0,_xlpm.a="none",0,_xlpm.a="moderate",1,_xlpm.a="strong",2), _xlpm.y,_xlfn.IFS(_xlpm.b="0",0,_xlpm.b="none",0,_xlpm.b="moderate",1,_xlpm.b="strong",2), _xlpm.d,ABS(_xlpm.x-_xlpm.y), IF(_xlpm.d=0,"green",IF(_xlpm.d=1,"orange",IF(_xlpm.d=2,"red","check"))) )} -> green | EB13: {=_xlfn.LET( _xlpm.a,LOWER(TRIM(DW13&"")), _xlpm.b,LOWER(TRIM(DX13&"")), _xlpm.x,_xlfn.IFS(_xlpm.a="0",0,_xlpm.a="none",0,_xlpm.a="moderate",1,_xlpm.a="strong",2), _xlpm.y,_xlfn.IFS(_xlpm.b="0",0,_xlpm.b="none",0,_xlpm.b="moderate",1,_xlpm.b="strong",2), _xlpm.d,ABS(_xlpm.x-_xlpm.y), IF(_xlpm.d=0,"green",IF(_xlpm.d=1,"orange",IF(_xlpm.d=2,"red","check"))) )} -> green | ES13: =IFERROR(VALUE(_xlfn.TEXTBEFORE(_xlfn.TEXTAFTER(AC13,"""84a544d4-0c20-4f9f-bb4b-dd698a9b0c0b"":"),",")),IFERROR(VALUE(_xlfn.TEXTBEFORE(_xlfn.TEXTAFTER(AC13,"""84a544d4-0c20-4f9f-bb4b-dd698a9b0c0b"":"),"}")),IFERROR(VALUE(_xlfn.TEXTBEFORE(_xlfn.TEXTAFTER(AC13,"""784c5905-6667-4dcd-906c-8b405a6572b6"":"),",")),IFERROR(VALUE(_xlfn.TEXTBEFORE(_xlfn.TEXTAFTER(AC13,"""784c5905-6667-4dcd-906c-8b405a6572b6"":"),"}")),"")))) | ET13: =IF(OR(DF13="Strong",DF13="Moderate",DJ13="Strong",DJ13="Moderate",DN13="Strong",DN13="Moderate"),"Yes","No") -> No | EU13: =IF(AND(DE13>=3,DD13=1),"Positive concordance",IF(AND(DE13>=3,DD13>=2),"Gap",IF(AND(DE13<=2,DD13>=2),"Negative concordance","Uninformative"))) -> Uninformative | EV13: =IF(AND(DI13>=3,DH13=1),"Positive concordance",IF(AND(DI13>=3,DH13>=2),"Gap",IF(AND(DI13<=2,DH13>=2),"Negative concordance","Uninformative"))) -> Uninformative | EW13: =IF(AND(DM13>=3,DL13=1),"Positive concordance",IF(AND(DM13>=3,DL13>=2),"Gap",IF(AND(DM13<=2,DL13>=2),"Negative concordance","Uninformative"))) -> Uninformative | EX13: =IF(AND(DE13=4,DD13=1),"Positive concordance",IF(AND(DE13=4,DD13>=2),"Gap",IF(AND(DE13<=3,DD13>=2),"Negative concordance","Uninformative"))) -> Uninformative | EY13: =IF(AND(DI13=4,DH13=1),"Positive concordance",IF(AND(DI13=4,DH13>=2),"Gap",IF(AND(DI13<=3,DH13>=2),"Negative concordance","Uninformative"))) -> Uninformative | EZ13: =IF(AND(DM13=4,DL13=1),"Positive concordance",IF(AND(DM13=4,DL13>=2),"Gap",IF(AND(DM13<=3,DL13>=2),"Negative concordance","Uninformative"))) -> Uninformative | FA13: =IF(OR(EX13="Gap",EY13="Gap",EZ13="Gap"),"Yes","No") -> No
DQ14: =CR14 -> 0 | DR14: =DB14 -> 0 | DS14: =CT14 -> 0 | DT14: =DF14 -> 0 | DU14: =CV14 -> 0 | DV14: =DJ14 -> 0 | DW14: =CX14 -> 0 | DX14: =DN14 -> 0 | DY14: {=_xlfn.LET( _xlpm.a,LOWER(TRIM(DQ14&"")), _xlpm.b,LOWER(TRIM(DR14&"")), _xlpm.x,_xlfn.IFS(_xlpm.a="0",0,_xlpm.a="none",0,_xlpm.a="moderate",1,_xlpm.a="strong",2), _xlpm.y,_xlfn.IFS(_xlpm.b="0",0,_xlpm.b="none",0,_xlpm.b="moderate",1,_xlpm.b="strong",2), _xlpm.d,ABS(_xlpm.x-_xlpm.y), IF(_xlpm.d=0,"green",IF(_xlpm.d=1,"orange",IF(_xlpm.d=2,"red","check"))) )} -> green | DZ14: {=_xlfn.LET( _xlpm.a,LOWER(TRIM(DS14&"")), _xlpm.b,LOWER(TRIM(DT14&"")), _xlpm.x,_xlfn.IFS(_xlpm.a="0",0,_xlpm.a="none",0,_xlpm.a="moderate",1,_xlpm.a="strong",2), _xlpm.y,_xlfn.IFS(_xlpm.b="0",0,_xlpm.b="none",0,_xlpm.b="moderate",1,_xlpm.b="strong",2), _xlpm.d,ABS(_xlpm.x-_xlpm.y), IF(_xlpm.d=0,"green",IF(_xlpm.d=1,"orange",IF(_xlpm.d=2,"red","check"))) )} -> green | EA14: {=_xlfn.LET( _xlpm.a,LOWER(TRIM(DU14&"")), _xlpm.b,LOWER(TRIM(DV14&"")), _xlpm.x,_xlfn.IFS(_xlpm.a="0",0,_xlpm.a="none",0,_xlpm.a="moderate",1,_xlpm.a="strong",2), _xlpm.y,_xlfn.IFS(_xlpm.b="0",0,_xlpm.b="none",0,_xlpm.b="moderate",1,_xlpm.b="strong",2), _xlpm.d,ABS(_xlpm.x-_xlpm.y), IF(_xlpm.d=0,"green",IF(_xlpm.d=1,"orange",IF(_xlpm.d=2,"red","check"))) )} -> green | EB14: {=_xlfn.LET( _xlpm.a,LOWER(TRIM(DW14&"")), _xlpm.b,LOWER(TRIM(DX14&"")), _xlpm.x,_xlfn.IFS(_xlpm.a="0",0,_xlpm.a="none",0,_xlpm.a="moderate",1,_xlpm.a="strong",2), _xlpm.y,_xlfn.IFS(_xlpm.b="0",0,_xlpm.b="none",0,_xlpm.b="moderate",1,_xlpm.b="strong",2), _xlpm.d,ABS(_xlpm.x-_xlpm.y), IF(_xlpm.d=0,"green",IF(_xlpm.d=1,"orange",IF(_xlpm.d=2,"red","check"))) )} -> green | ES14: =IFERROR(VALUE(_xlfn.TEXTBEFORE(_xlfn.TEXTAFTER(AC14,"""84a544d4-0c20-4f9f-bb4b-dd698a9b0c0b"":"),",")),IFERROR(VALUE(_xlfn.TEXTBEFORE(_xlfn.TEXTAFTER(AC14,"""84a544d4-0c20-4f9f-bb4b-dd698a9b0c0b"":"),"}")),IFERROR(VALUE(_xlfn.TEXTBEFORE(_xlfn.TEXTAFTER(AC14,"""784c5905-6667-4dcd-906c-8b405a6572b6"":"),",")),IFERROR(VALUE(_xlfn.TEXTBEFORE(_xlfn.TEXTAFTER(AC14,"""784c5905-6667-4dcd-906c-8b405a6572b6"":"),"}")),"")))) | ET14: =IF(OR(DF14="Strong",DF14="Moderate",DJ14="Strong",DJ14="Moderate",DN14="Strong",DN14="Moderate"),"Yes","No") -> No | EU14: =IF(AND(DE14>=3,DD14=1),"Positive concordance",IF(AND(DE14>=3,DD14>=2),"Gap",IF(AND(DE14<=2,DD14>=2),"Negative concordance","Uninformative"))) -> Uninformative | EV14: =IF(AND(DI14>=3,DH14=1),"Positive concordance",IF(AND(DI14>=3,DH14>=2),"Gap",IF(AND(DI14<=2,DH14>=2),"Negative concordance","Uninformative"))) -> Uninformative | EW14: =IF(AND(DM14>=3,DL14=1),"Positive concordance",IF(AND(DM14>=3,DL14>=2),"Gap",IF(AND(DM14<=2,DL14>=2),"Negative concordance","Uninformative"))) -> Uninformative | EX14: =IF(AND(DE14=4,DD14=1),"Positive concordance",IF(AND(DE14=4,DD14>=2),"Gap",IF(AND(DE14<=3,DD14>=2),"Negative concordance","Uninformative"))) -> Uninformative | EY14: =IF(AND(DI14=4,DH14=1),"Positive concordance",IF(AND(DI14=4,DH14>=2),"Gap",IF(AND(DI14<=3,DH14>=2),"Negative concordance","Uninformative"))) -> Uninformative | EZ14: =IF(AND(DM14=4,DL14=1),"Positive concordance",IF(AND(DM14=4,DL14>=2),"Gap",IF(AND(DM14<=3,DL14>=2),"Negative concordance","Uninformative"))) -> Uninformative | FA14: =IF(OR(EX14="Gap",EY14="Gap",EZ14="Gap"),"Yes","No") -> No
... DQ105: =CR105 -> 0 | DR105: =DB105 -> 0 | DS105: =CT105 -> 0 | DT105: =DF105 -> 0 | DU105: =CV105 -> 0 | DV105: =DJ105 -> 0 | DW105: =CX105 -> 0 | DX105: =DN105 -> 0 | DY105: {=_xlfn.LET( _xlpm.a,LOWER(TRIM(DQ105&"")), _xlpm.b,LOWER(TRIM(DR105&"")), _xlpm.x,_xlfn.IFS(_xlpm.a="0",0,_xlpm.a="none",0,_xlpm.a="moderate",1,_xlpm.a="strong",2), _xlpm.y,_xlfn.IFS(_xlpm.b="0",0,_xlpm.b="none",0,_xlpm.b="moderate",1,_xlpm.b="strong",2), _xlpm.d,ABS(_xlpm.x-_xlpm.y), IF(_xlpm.d=0,"green",IF(_xlpm.d=1,"orange",IF(_xlpm.d=2,"red","check"))) )} -> green | DZ105: {=_xlfn.LET( _xlpm.a,LOWER(TRIM(DS105&"")), _xlpm.b,LOWER(TRIM(DT105&"")), _xlpm.x,_xlfn.IFS(_xlpm.a="0",0,_xlpm.a="none",0,_xlpm.a="moderate",1,_xlpm.a="strong",2), _xlpm.y,_xlfn.IFS(_xlpm.b="0",0,_xlpm.b="none",0,_xlpm.b="moderate",1,_xlpm.b="strong",2), _xlpm.d,ABS(_xlpm.x-_xlpm.y), IF(_xlpm.d=0,"green",IF(_xlpm.d=1,"orange",IF(_xlpm.d=2,"red","check"))) )} -> green | EA105: {=_xlfn.LET( _xlpm.a,LOWER(TRIM(DU105&"")), _xlpm.b,LOWER(TRIM(DV105&"")), _xlpm.x,_xlfn.IFS(_xlpm.a="0",0,_xlpm.a="none",0,_xlpm.a="moderate",1,_xlpm.a="strong",2), _xlpm.y,_xlfn.IFS(_xlpm.b="0",0,_xlpm.b="none",0,_xlpm.b="moderate",1,_xlpm.b="strong",2), _xlpm.d,ABS(_xlpm.x-_xlpm.y), IF(_xlpm.d=0,"green",IF(_xlpm.d=1,"orange",IF(_xlpm.d=2,"red","check"))) )} -> green | EB105: {=_xlfn.LET( _xlpm.a,LOWER(TRIM(DW105&"")), _xlpm.b,LOWER(TRIM(DX105&"")), _xlpm.x,_xlfn.IFS(_xlpm.a="0",0,_xlpm.a="none",0,_xlpm.a="moderate",1,_xlpm.a="strong",2), _xlpm.y,_xlfn.IFS(_xlpm.b="0",0,_xlpm.b="none",0,_xlpm.b="moderate",1,_xlpm.b="strong",2), _xlpm.d,ABS(_xlpm.x-_xlpm.y), IF(_xlpm.d=0,"green",IF(_xlpm.d=1,"orange",IF(_xlpm.d=2,"red","check"))) )} -> green | ES105: =IFERROR(VALUE(_xlfn.TEXTBEFORE(_xlfn.TEXTAFTER(AC105,"""84a544d4-0c20-4f9f-bb4b-dd698a9b0c0b"":"),",")),IFERROR(VALUE(_xlfn.TEXTBEFORE(_xlfn.TEXTAFTER(AC105,"""84a544d4-0c20-4f9f-bb4b-dd698a9b0c0b"":"),"}")),IFERROR(VALUE(_xlfn.TEXTBEFORE(_xlfn.TEXTAFTER(AC105,"""784c5905-6667-4dcd-906c-8b405a6572b6"":"),",")),IFERROR(VALUE(_xlfn.TEXTBEFORE(_xlfn.TEXTAFTER(AC105,"""784c5905-6667-4dcd-906c-8b405a6572b6"":"),"}")),"")))) | ET105: =IF(OR(DF105="Strong",DF105="Moderate",DJ105="Strong",DJ105="Moderate",DN105="Strong",DN105="Moderate"),"Yes","No") -> No | EU105: =IF(AND(DE105>=3,DD105=1),"Positive concordance",IF(AND(DE105>=3,DD105>=2),"Gap",IF(AND(DE105<=2,DD105>=2),"Negative concordance","Uninformative"))) -> Uninformative | EV105: =IF(AND(DI105>=3,DH105=1),"Positive concordance",IF(AND(DI105>=3,DH105>=2),"Gap",IF(AND(DI105<=2,DH105>=2),"Negative concordance","Uninformative"))) -> Uninformative | EW105: =IF(AND(DM105>=3,DL105=1),"Positive concordance",IF(AND(DM105>=3,DL105>=2),"Gap",IF(AND(DM105<=2,DL105>=2),"Negative concordance","Uninformative"))) -> Uninformative | EX105: =IF(AND(DE105=4,DD105=1),"Positive concordance",IF(AND(DE105=4,DD105>=2),"Gap",IF(AND(DE105<=3,DD105>=2),"Negative concordance","Uninformative"))) -> Uninformative | EY105: =IF(AND(DI105=4,DH105=1),"Positive concordance",IF(AND(DI105=4,DH105>=2),"Gap",IF(AND(DI105<=3,DH105>=2),"Negative concordance","Uninformative"))) -> Uninformative | EZ105: =IF(AND(DM105=4,DL105=1),"Positive concordance",IF(AND(DM105=4,DL105>=2),"Gap",IF(AND(DM105<=3,DL105>=2),"Negative concordance","Uninformative"))) -> Uninformative | FA105: =IF(OR(EX105="Gap",EY105="Gap",EZ105="Gap"),"Yes","No") -> No

Sheet Qualitative Analysis
A1: Session_ID | B1: Interview_Number | C1: Response_JSON | D1: Quote | E1: Topic | F1: Flaggin_Reason | G1: First_Code_Label | H1: Confidence_Score | I1: Second_Order | J1: Second_Order_Clustered | K1: Third_Order | L1: My_Manual_Code | M1: Include_Flag | N1: Gap (Yes/No)
A2: 01fe93a8-8723-48be-9311-b6d08c34a13d | B2: 1 | C2: {"session_id": "01fe93a8-8723-48be-9311-b6d08c34a13d", "quotes": [{"quote_text": "I was a little bit sick, but not too bad. Just wanted not to overdo it.", "topic": "workload_sustainability", "first_order_code": "minimizing illness to avoid overdoing it", "flagging_reason": "Participant softens being sick with 'not too bad' while explaining a self-protective boundary around workload.", "confidence": 0.75}, {"quote_text": "especially because our project lead was in the US. Um, so we could align, uh, on the, uh, associate and consultant level a lot better on tasks that we needed to do. Um, and by the time that he was awake in Pacific time, we could already iterate documents with him.", "topic": "overall_experience", "first_order_code": "working around time zone gap with project lead", "flagging_reason": "Describes a workaround necessitated by the project lead's remote location and time difference, indicating a friction point.", "confidence": 0.7}, {"quote_text": "I think the senior leadership, the more sen- the senior partners, they are more hands-off, which is totally okay and acceptable because the project has been going on for such a long time, so there's not a lot that they need to escalate.", "topic": "leadership_engagement", "first_order_code": "justifying senior partners being hands-off", "flagging_reason": "Participant describes limited senior partner involvement but immediately rationalizes it as acceptable, suggesting potential concern being defused.", "confidence": 0.65}]} | D2: I think the senior leadership, the more sen- the senior partners, they are more hands-off, which is totally okay and acceptable because the project has been going on for such a long time, so there's not a lot that they need to escalate. | E2: leadership | F2: Participant describes limited senior partner involvement but immediately rationalizes it as acceptable, suggesting potential concern being defused. | G2: justifying senior partners being hands-off | H2: 0.65 | I2: Rationalizing leadership absence | J2: =IF(OR(I2="Epistemic hedging",I2="Qualifying severity while disclosing",I2="Downgrading emotional intensity"),"Hedged, qualified disclosure",IF(OR(I2="Externalizing accountability",I2="Self-attributing structural problems"),"Protective attribution shifting",IF(OR(I2="Refusal to elaborate under probing",I2="Retracting or qualifying disclosure"),"Withholding under probing",IF(OR(I2="Managing traceability and exposure",I2="Compartmentalizing the AI channel"),"Channel exposure management",IF(OR(I2="Skepticism toward remedy",I2="Anticipating dismissal or misrecognition"),"Anticipated futility of voice",IF(OR(I2="Calling out known but unaddressed issues",I2="Silence within expression"),"Recognized but unescalated concerns",I2)))))) -> Rationalizing leadership absence | K2: =_xlfn.XLOOKUP(J2,#REF!,#REF!,"0",0,1) -> #REF! | N2: =IFERROR(INDEX('Hoja 1 - Supabase Transcripts'!$A:$DN,MATCH(A2,'Hoja 1 - Supabase Transcripts'!$A:$A,0),MATCH("gap_segmentation_"&E2,'Hoja 1 - Supabase Transcripts'!$2:$2,0)),"not found") -> not found | R2: =COUNTA(_xlfn.UNIQUE(A2:A429)) -> 79
A3: 01fe93a8-8723-48be-9311-b6d08c34a13d | B3: 1 | C3: {"session_id": "01fe93a8-8723-48be-9311-b6d08c34a13d", "quotes": [{"quote_text": "I was a little bit sick, but not too bad. Just wanted not to overdo it.", "topic": "workload_sustainability", "first_order_code": "minimizing illness to avoid overdoing it", "flagging_reason": "Participant softens being sick with 'not too bad' while explaining a self-protective boundary around workload.", "confidence": 0.75}, {"quote_text": "especially because our project lead was in the US. Um, so we could align, uh, on the, uh, associate and consultant level a lot better on tasks that we needed to do. Um, and by the time that he was awake in Pacific time, we could already iterate documents with him.", "topic": "overall_experience", "first_order_code": "working around time zone gap with project lead", "flagging_reason": "Describes a workaround necessitated by the project lead's remote location and time difference, indicating a friction point.", "confidence": 0.7}, {"quote_text": "I think the senior leadership, the more sen- the senior partners, they are more hands-off, which is totally okay and acceptable because the project has been going on for such a long time, so there's not a lot that they need to escalate.", "topic": "leadership_engagement", "first_order_code": "justifying senior partners being hands-off", "flagging_reason": "Participant describes limited senior partner involvement but immediately rationalizes it as acceptable, suggesting potential concern being defused.", "confidence": 0.65}]} | D3: especially because our project lead was in the US. Um, so we could align, uh, on the, uh, associate and consultant level a lot better on tasks that we needed to do. Um, and by the time that he was awake in Pacific time, we could already iterate documents with him. | E3: overall_experience | F3: Describes a workaround necessitated by the project lead's remote location and time difference, indicating a friction point. | G3: working around time zone gap with project lead | H3: 0.7 | I3: Concern content - FAMILY A | J3: =IF(OR(I3="Epistemic hedging",I3="Qualifying severity while disclosing",I3="Downgrading emotional intensity"),"Hedged, qualified disclosure",IF(OR(I3="Externalizing accountability",I3="Self-attributing structural problems"),"Protective attribution shifting",IF(OR(I3="Refusal to elaborate under probing",I3="Retracting or qualifying disclosure"),"Withholding under probing",IF(OR(I3="Managing traceability and exposure",I3="Compartmentalizing the AI channel"),"Channel exposure management",IF(OR(I3="Skepticism toward remedy",I3="Anticipating dismissal or misrecognition"),"Anticipated futility of voice",IF(OR(I3="Calling out known but unaddressed issues",I3="Silence within expression"),"Recognized but unescalated concerns",I3)))))) -> Concern content - FAMILY A | N3: =IFERROR(INDEX('Hoja 1 - Supabase Transcripts'!$A:$DN,MATCH(A3,'Hoja 1 - Supabase Transcripts'!$A:$A,0),MATCH("gap_segmentation_"&E3,'Hoja 1 - Supabase Transcripts'!$2:$2,0)),"not found") -> not found
A4: 01fe93a8-8723-48be-9311-b6d08c34a13d | B4: 1 | C4: {"session_id": "01fe93a8-8723-48be-9311-b6d08c34a13d", "quotes": [{"quote_text": "I was a little bit sick, but not too bad. Just wanted not to overdo it.", "topic": "workload_sustainability", "first_order_code": "minimizing illness to avoid overdoing it", "flagging_reason": "Participant softens being sick with 'not too bad' while explaining a self-protective boundary around workload.", "confidence": 0.75}, {"quote_text": "especially because our project lead was in the US. Um, so we could align, uh, on the, uh, associate and consultant level a lot better on tasks that we needed to do. Um, and by the time that he was awake in Pacific time, we could already iterate documents with him.", "topic": "overall_experience", "first_order_code": "working around time zone gap with project lead", "flagging_reason": "Describes a workaround necessitated by the project lead's remote location and time difference, indicating a friction point.", "confidence": 0.7}, {"quote_text": "I think the senior leadership, the more sen- the senior partners, they are more hands-off, which is totally okay and acceptable because the project has been going on for such a long time, so there's not a lot that they need to escalate.", "topic": "leadership_engagement", "first_order_code": "justifying senior partners being hands-off", "flagging_reason": "Participant describes limited senior partner involvement but immediately rationalizes it as acceptable, suggesting potential concern being defused.", "confidence": 0.65}]} | D4: I was a little bit sick, but not too bad. Just wanted not to overdo it. | E4: workload_sust | F4: Participant softens being sick with 'not too bad' while explaining a self-protective boundary around workload. | G4: minimizing illness to avoid overdoing it | H4: 0.75 | I4: Downgrading emotional intensity | J4: =IF(OR(I4="Epistemic hedging",I4="Qualifying severity while disclosing",I4="Downgrading emotional intensity"),"Hedged, qualified disclosure",IF(OR(I4="Externalizing accountability",I4="Self-attributing structural problems"),"Protective attribution shifting",IF(OR(I4="Refusal to elaborate under probing",I4="Retracting or qualifying disclosure"),"Withholding under probing",IF(OR(I4="Managing traceability and exposure",I4="Compartmentalizing the AI channel"),"Channel exposure management",IF(OR(I4="Skepticism toward remedy",I4="Anticipating dismissal or misrecognition"),"Anticipated futility of voice",IF(OR(I4="Calling out known but unaddressed issues",I4="Silence within expression"),"Recognized but unescalated concerns",I4)))))) -> Hedged, qualified disclosure | K4: =_xlfn.XLOOKUP(J4,#REF!,#REF!,"0",0,1) -> #REF! | N4: =IFERROR(INDEX('Hoja 1 - Supabase Transcripts'!$A:$DN,MATCH(A4,'Hoja 1 - Supabase Transcripts'!$A:$A,0),MATCH("gap_segmentation_"&E4,'Hoja 1 - Supabase Transcripts'!$2:$2,0)),"not found") -> not found
